<?xml version="1.0" encoding="utf-8"?>
<!-- =================================================================================== -->
<!-- |    This document was autogenerated by xacro from /home/ubuntu-ros/catkin_ws/src/snake/urdf/modello.xacro | -->
<!-- |    EDITING THIS FILE BY HAND IS NOT RECOMMENDED                                 | -->
<!-- =================================================================================== -->
<robot name="snake" xmlns:xacro="http://ros.org/wiki/xacro">
  <material name="red">
    <color rgba="1 0 0 1"/>
  </material>
  <material name="green">
    <color rgba="0 1 0 1"/>
  </material>
  <material name="blue">
    <color rgba="0 0 1 1"/>
  </material>
  <link name="link0">
    <visual>
      <origin xyz="0 0 0.15"/>
      <geometry>
        <cylinder length="0.3" radius="0.05"/>
      </geometry>
      <material name="red"/>
    </visual>
  </link>
  <link name="link1">
    <visual>
      <origin xyz="0 0 0.15"/>
      <geometry>
        <cylinder length="0.3" radius="0.05"/>
      </geometry>
      <material name="green"/>
    </visual>
  </link>
  <link name="link2">
    <visual>
      <origin xyz="0 0 0.15"/>
      <geometry>
        <cylinder length="0.3" radius="0.05"/>
      </geometry>
      <material name="blue"/>
    </visual>
  </link>
  <link name="link3">
    <visual>
      <origin xyz="0 0 0.15"/>
      <geometry>
        <cylinder length="0.3" radius="0.05"/>
      </geometry>
      <material name="red"/>
    </visual>
  </link>
  <link name="link4">
    <visual>
      <origin xyz="0 0 0.15"/>
      <geometry>
        <cylinder length="0.3" radius="0.05"/>
      </geometry>
      <material name="green"/>
    </visual>
  </link>
  <link name="link5">
    <visual>
      <origin xyz="0 0 0.15"/>
      <geometry>
        <cylinder length="0.3" radius="0.05"/>
      </geometry>
      <material name="blue"/>
    </visual>
  </link>
  <link name="link6">
    <visual>
      <origin xyz="0 0 0.15"/>
      <geometry>
        <cylinder length="0.3" radius="0.05"/>
      </geometry>
      <material name="red"/>
    </visual>
  </link>
  <link name="link7">
    <visual>
      <origin xyz="0 0 0.15"/>
      <geometry>
        <cylinder length="0.3" radius="0.05"/>
      </geometry>
      <material name="green"/>
    </visual>
  </link>
  <link name="link8">
    <visual>
      <origin xyz="0 0 0.15"/>
      <geometry>
        <cylinder length="0.3" radius="0.05"/>
      </geometry>
      <material name="blue"/>
    </visual>
  </link>
  <link name="link9">
    <visual>
      <origin xyz="0 0 0.15"/>
      <geometry>
        <cylinder length="0.3" radius="0.05"/>
      </geometry>
      <material name="red"/>
    </visual>
  </link>
  <link name="link10">
    <visual>
      <origin xyz="0 0 0.15"/>
      <geometry>
        <cylinder length="0.3" radius="0.05"/>
      </geometry>
      <material name="green"/>
    </visual>
  </link>
  <link name="link11">
    <visual>
      <origin xyz="0 0 0.15"/>
      <geometry>
        <cylinder length="0.3" radius="0.05"/>
      </geometry>
      <material name="blue"/>
    </visual>
  </link>
  <link name="link12">
    <visual>
      <origin xyz="0 0 0.15"/>
      <geometry>
        <cylinder length="0.3" radius="0.05"/>
      </geometry>
      <material name="red"/>
    </visual>
  </link>
  <link name="link13">
    <visual>
      <origin xyz="0 0 0.15"/>
      <geometry>
        <cylinder length="0.3" radius="0.05"/>
      </geometry>
      <material name="green"/>
    </visual>
  </link>
  <link name="link14">
    <visual>
      <origin xyz="0 0 0.15"/>
      <geometry>
        <cylinder length="0.3" radius="0.05"/>
      </geometry>
      <material name="blue"/>
    </visual>
  </link>
  <joint name="joint0" type="revolute">
    <parent link="link0"/>
    <child link="link1"/>
    <axis xyz="1 0 0"/>
    <origin xyz="0 0 0.3"/>
    <limit effort="100" lower="-0.785398163397" upper="0.785398163397" velocity="100"/>
  </joint>
  <joint name="joint1" type="revolute">
    <parent link="link1"/>
    <child link="link2"/>
    <axis xyz="0 1 0"/>
    <origin xyz="0 0 0.3"/>
    <limit effort="100" lower="-0.785398163397" upper="0.785398163397" velocity="100"/>
  </joint>
  <joint name="joint2" type="revolute">
    <parent link="link2"/>
    <child link="link3"/>
    <axis xyz="1 0 0"/>
    <origin xyz="0 0 0.3"/>
    <limit effort="100" lower="-0.785398163397" upper="0.785398163397" velocity="100"/>
  </joint>
  <joint name="joint3" type="revolute">
    <parent link="link3"/>
    <child link="link4"/>
    <axis xyz="0 1 0"/>
    <origin xyz="0 0 0.3"/>
    <limit effort="100" lower="-0.785398163397" upper="0.785398163397" velocity="100"/>
  </joint>
  <joint name="joint4" type="revolute">
    <parent link="link4"/>
    <child link="link5"/>
    <axis xyz="1 0 0"/>
    <origin xyz="0 0 0.3"/>
    <limit effort="100" lower="-0.785398163397" upper="0.785398163397" velocity="100"/>
  </joint>
  <joint name="joint5" type="revolute">
    <parent link="link5"/>
    <child link="link6"/>
    <axis xyz="0 1 0"/>
    <origin xyz="0 0 0.3"/>
    <limit effort="100" lower="-0.785398163397" upper="0.785398163397" velocity="100"/>
  </joint>
  <joint name="joint6" type="revolute">
    <parent link="link6"/>
    <child link="link7"/>
    <axis xyz="1 0 0"/>
    <origin xyz="0 0 0.3"/>
    <limit effort="100" lower="-0.785398163397" upper="0.785398163397" velocity="100"/>
  </joint>
  <joint name="joint7" type="revolute">
    <parent link="link7"/>
    <child link="link8"/>
    <axis xyz="0 1 0"/>
    <origin xyz="0 0 0.3"/>
    <limit effort="100" lower="-0.785398163397" upper="0.785398163397" velocity="100"/>
  </joint>
  <joint name="joint8" type="revolute">
    <parent link="link8"/>
    <child link="link9"/>
    <axis xyz="1 0 0"/>
    <origin xyz="0 0 0.3"/>
    <limit effort="100" lower="-0.785398163397" upper="0.785398163397" velocity="100"/>
  </joint>
  <joint name="joint9" type="revolute">
    <parent link="link9"/>
    <child link="link10"/>
    <axis xyz="0 1 0"/>
    <origin xyz="0 0 0.3"/>
    <limit effort="100" lower="-0.785398163397" upper="0.785398163397" velocity="100"/>
  </joint>
  <joint name="joint10" type="revolute">
    <parent link="link10"/>
    <child link="link11"/>
    <axis xyz="1 0 0"/>
    <origin xyz="0 0 0.3"/>
    <limit effort="100" lower="-0.785398163397" upper="0.785398163397" velocity="100"/>
  </joint>
  <joint name="joint11" type="revolute">
    <parent link="link11"/>
    <child link="link12"/>
    <axis xyz="0 1 0"/>
    <origin xyz="0 0 0.3"/>
    <limit effort="100" lower="-0.785398163397" upper="0.785398163397" velocity="100"/>
  </joint>
  <joint name="joint12" type="revolute">
    <parent link="link12"/>
    <child link="link13"/>
    <axis xyz="1 0 0"/>
    <origin xyz="0 0 0.3"/>
    <limit effort="100" lower="-0.785398163397" upper="0.785398163397" velocity="100"/>
  </joint>
  <joint name="joint13" type="revolute">
    <parent link="link13"/>
    <child link="link14"/>
    <axis xyz="0 1 0"/>
    <origin xyz="0 0 0.3"/>
    <limit effort="100" lower="-0.785398163397" upper="0.785398163397" velocity="100"/>
  </joint>
</robot>
