<?xml version="1.0" ?>
<robot name="snake" xmlns:xacro="http://ros.org/wiki/xacro">
  <material name="color_a">
    <color rgba="0 0 0 1"/>
  </material>
  <material name="color_b">
    <color rgba="0 0 1 1"/>
  </material>
  <material name="color_c">
    <color rgba="0 1 0 1"/>
  </material>
  <material name="color_d">
    <color rgba="0 1 1 1"/>
  </material>
  <material name="color_e">
    <color rgba="1 0 0 1"/>
  </material>
  <material name="color_f">
    <color rgba="1 0 1 1"/>
  </material>
  <material name="color_g">
    <color rgba="1 1 0 1"/>
  </material>
  <material name="color_h">
    <color rgba="1 1 1 1"/>
  </material>
  <link name="link0">
    <visual>
      <origin xyz="0 0 5e-06"/>
      <material name="color_a"/>
      <geometry>
        <cylinder length="1e-05" radius="0.01"/>
      </geometry>
    </visual>
  </link>
  <link name="link1">
    <visual>
      <origin xyz="0 0 0.05"/>
      <material name="color_b"/>
      <geometry>
        <cylinder length="0.1" radius="0.01"/>
      </geometry>
    </visual>
  </link>
  <link name="link2">
    <visual>
      <origin xyz="0 0 5e-06"/>
      <material name="color_c"/>
      <geometry>
        <cylinder length="1e-05" radius="0.01"/>
      </geometry>
    </visual>
  </link>
  <link name="link3">
    <visual>
      <origin xyz="0 0 0.05"/>
      <material name="color_d"/>
      <geometry>
        <cylinder length="0.1" radius="0.01"/>
      </geometry>
    </visual>
  </link>
  <link name="link4">
    <visual>
      <origin xyz="0 0 5e-06"/>
      <material name="color_e"/>
      <geometry>
        <cylinder length="1e-05" radius="0.01"/>
      </geometry>
    </visual>
  </link>
  <link name="link5">
    <visual>
      <origin xyz="0 0 0.05"/>
      <material name="color_f"/>
      <geometry>
        <cylinder length="0.1" radius="0.01"/>
      </geometry>
    </visual>
  </link>
  <link name="link6">
    <visual>
      <origin xyz="0 0 5e-06"/>
      <material name="color_g"/>
      <geometry>
        <cylinder length="1e-05" radius="0.01"/>
      </geometry>
    </visual>
  </link>
  <link name="link7">
    <visual>
      <origin xyz="0 0 0.05"/>
      <material name="color_h"/>
      <geometry>
        <cylinder length="0.1" radius="0.01"/>
      </geometry>
    </visual>
  </link>
  <joint name="joint0" type="revolute">
    <parent link="link0"/>
    <child link="link1"/>
    <axis xyz="1 0 0"/>
    <origin xyz="0 0 1e-05"/>
    <limit effort="100" lower="-1.57" upper="1.57" velocity="100"/>
  </joint>
  <joint name="joint1" type="revolute">
    <parent link="link1"/>
    <child link="link2"/>
    <axis xyz="0 1 0"/>
    <origin xyz="0 0 0.1"/>
    <limit effort="100" lower="-1.57" upper="1.57" velocity="100"/>
  </joint>
  <joint name="joint2" type="revolute">
    <parent link="link2"/>
    <child link="link3"/>
    <axis xyz="1 0 0"/>
    <origin xyz="0 0 1e-05"/>
    <limit effort="100" lower="-1.57" upper="1.57" velocity="100"/>
  </joint>
  <joint name="joint3" type="revolute">
    <parent link="link3"/>
    <child link="link4"/>
    <axis xyz="0 1 0"/>
    <origin xyz="0 0 0.1"/>
    <limit effort="100" lower="-1.57" upper="1.57" velocity="100"/>
  </joint>
  <joint name="joint4" type="revolute">
    <parent link="link4"/>
    <child link="link5"/>
    <axis xyz="1 0 0"/>
    <origin xyz="0 0 1e-05"/>
    <limit effort="100" lower="-1.57" upper="1.57" velocity="100"/>
  </joint>
  <joint name="joint5" type="revolute">
    <parent link="link5"/>
    <child link="link6"/>
    <axis xyz="0 1 0"/>
    <origin xyz="0 0 0.1"/>
    <limit effort="100" lower="-1.57" upper="1.57" velocity="100"/>
  </joint>
  <joint name="joint6" type="revolute">
    <parent link="link6"/>
    <child link="link7"/>
    <axis xyz="1 0 0"/>
    <origin xyz="0 0 1e-05"/>
    <limit effort="100" lower="-1.57" upper="1.57" velocity="100"/>
  </joint>
  <material name="end_effector_material">
    <color rgba="1 1 1 1"/>
  </material>
  <link name="end_effector">
    <visual>
      <origin xyz="0 0 0.1"/>
      <material name="end_effector_material"/>
      <geometry>
        <sphere radius="0.1"/>
      </geometry>
    </visual>
  </link>
  <joint name="joint_end_effector" type="fixed">
    <parent link="link7"/>
    <child link="end_effector"/>
    <limit effort="100" lower="-1.57" upper="1.57" velocity="100"/>
  </joint>
</robot>

