<?xml version="1.0" ?>
<robot name="snake" xmlns:xacro="http://ros.org/wiki/xacro">
  <material name="color_a">
    <color rgba="0 0 0 1"/>
  </material>
  <material name="color_b">
    <color rgba="0 0 1 1"/>
  </material>
  <material name="color_c">
    <color rgba="0 1 0 1"/>
  </material>
  <material name="color_d">
    <color rgba="0 1 1 1"/>
  </material>
  <material name="color_e">
    <color rgba="1 0 0 1"/>
  </material>
  <material name="color_f">
    <color rgba="1 0 1 1"/>
  </material>
  <material name="color_g">
    <color rgba="1 1 0 1"/>
  </material>
  <material name="color_h">
    <color rgba="1 1 1 1"/>
  </material>
  <link name="link0">
    <visual>
      <origin xyz="0 0 5e-06"/>
      <material name="color_a"/>
      <geometry>
        <cylinder length="1e-05" radius="0.01"/>
      </geometry>
    </visual>
  </link>
  <link name="link1">
    <visual>
      <origin xyz="0 0 0.05"/>
      <material name="color_b"/>
      <geometry>
        <cylinder length="0.1" radius="0.01"/>
      </geometry>
    </visual>
  </link>
  <link name="link2">
    <visual>
      <origin xyz="0 0 5e-06"/>
      <material name="color_c"/>
      <geometry>
        <cylinder length="1e-05" radius="0.01"/>
      </geometry>
    </visual>
  </link>
  <link name="link3">
    <visual>
      <origin xyz="0 0 0.05"/>
      <material name="color_d"/>
      <geometry>
        <cylinder length="0.1" radius="0.01"/>
      </geometry>
    </visual>
  </link>
  <link name="link4">
    <visual>
      <origin xyz="0 0 5e-06"/>
      <material name="color_e"/>
      <geometry>
        <cylinder length="1e-05" radius="0.01"/>
      </geometry>
    </visual>
  </link>
  <link name="link5">
    <visual>
      <origin xyz="0 0 0.05"/>
      <material name="color_f"/>
      <geometry>
        <cylinder length="0.1" radius="0.01"/>
      </geometry>
    </visual>
  </link>
  <link name="link6">
    <visual>
      <origin xyz="0 0 5e-06"/>
      <material name="color_g"/>
      <geometry>
        <cylinder length="1e-05" radius="0.01"/>
      </geometry>
    </visual>
  </link>
  <link name="link7">
    <visual>
      <origin xyz="0 0 0.05"/>
      <material name="color_h"/>
      <geometry>
        <cylinder length="0.1" radius="0.01"/>
      </geometry>
    </visual>
  </link>
  <link name="link8">
    <visual>
      <origin xyz="0 0 5e-06"/>
      <material name="color_a"/>
      <geometry>
        <cylinder length="1e-05" radius="0.01"/>
      </geometry>
    </visual>
  </link>
  <link name="link9">
    <visual>
      <origin xyz="0 0 0.05"/>
      <material name="color_b"/>
      <geometry>
        <cylinder length="0.1" radius="0.01"/>
      </geometry>
    </visual>
  </link>
  <link name="link10">
    <visual>
      <origin xyz="0 0 5e-06"/>
      <material name="color_c"/>
      <geometry>
        <cylinder length="1e-05" radius="0.01"/>
      </geometry>
    </visual>
  </link>
  <link name="link11">
    <visual>
      <origin xyz="0 0 0.05"/>
      <material name="color_d"/>
      <geometry>
        <cylinder length="0.1" radius="0.01"/>
      </geometry>
    </visual>
  </link>
  <link name="link12">
    <visual>
      <origin xyz="0 0 5e-06"/>
      <material name="color_e"/>
      <geometry>
        <cylinder length="1e-05" radius="0.01"/>
      </geometry>
    </visual>
  </link>
  <link name="link13">
    <visual>
      <origin xyz="0 0 0.05"/>
      <material name="color_f"/>
      <geometry>
        <cylinder length="0.1" radius="0.01"/>
      </geometry>
    </visual>
  </link>
  <link name="link14">
    <visual>
      <origin xyz="0 0 5e-06"/>
      <material name="color_g"/>
      <geometry>
        <cylinder length="1e-05" radius="0.01"/>
      </geometry>
    </visual>
  </link>
  <link name="link15">
    <visual>
      <origin xyz="0 0 0.05"/>
      <material name="color_h"/>
      <geometry>
        <cylinder length="0.1" radius="0.01"/>
      </geometry>
    </visual>
  </link>
  <link name="link16">
    <visual>
      <origin xyz="0 0 5e-06"/>
      <material name="color_a"/>
      <geometry>
        <cylinder length="1e-05" radius="0.01"/>
      </geometry>
    </visual>
  </link>
  <link name="link17">
    <visual>
      <origin xyz="0 0 0.05"/>
      <material name="color_b"/>
      <geometry>
        <cylinder length="0.1" radius="0.01"/>
      </geometry>
    </visual>
  </link>
  <link name="link18">
    <visual>
      <origin xyz="0 0 5e-06"/>
      <material name="color_c"/>
      <geometry>
        <cylinder length="1e-05" radius="0.01"/>
      </geometry>
    </visual>
  </link>
  <link name="link19">
    <visual>
      <origin xyz="0 0 0.05"/>
      <material name="color_d"/>
      <geometry>
        <cylinder length="0.1" radius="0.01"/>
      </geometry>
    </visual>
  </link>
  <link name="link20">
    <visual>
      <origin xyz="0 0 5e-06"/>
      <material name="color_e"/>
      <geometry>
        <cylinder length="1e-05" radius="0.01"/>
      </geometry>
    </visual>
  </link>
  <link name="link21">
    <visual>
      <origin xyz="0 0 0.05"/>
      <material name="color_f"/>
      <geometry>
        <cylinder length="0.1" radius="0.01"/>
      </geometry>
    </visual>
  </link>
  <link name="link22">
    <visual>
      <origin xyz="0 0 5e-06"/>
      <material name="color_g"/>
      <geometry>
        <cylinder length="1e-05" radius="0.01"/>
      </geometry>
    </visual>
  </link>
  <link name="link23">
    <visual>
      <origin xyz="0 0 0.05"/>
      <material name="color_h"/>
      <geometry>
        <cylinder length="0.1" radius="0.01"/>
      </geometry>
    </visual>
  </link>
  <link name="link24">
    <visual>
      <origin xyz="0 0 5e-06"/>
      <material name="color_a"/>
      <geometry>
        <cylinder length="1e-05" radius="0.01"/>
      </geometry>
    </visual>
  </link>
  <link name="link25">
    <visual>
      <origin xyz="0 0 0.05"/>
      <material name="color_b"/>
      <geometry>
        <cylinder length="0.1" radius="0.01"/>
      </geometry>
    </visual>
  </link>
  <link name="link26">
    <visual>
      <origin xyz="0 0 5e-06"/>
      <material name="color_c"/>
      <geometry>
        <cylinder length="1e-05" radius="0.01"/>
      </geometry>
    </visual>
  </link>
  <link name="link27">
    <visual>
      <origin xyz="0 0 0.05"/>
      <material name="color_d"/>
      <geometry>
        <cylinder length="0.1" radius="0.01"/>
      </geometry>
    </visual>
  </link>
  <link name="link28">
    <visual>
      <origin xyz="0 0 5e-06"/>
      <material name="color_e"/>
      <geometry>
        <cylinder length="1e-05" radius="0.01"/>
      </geometry>
    </visual>
  </link>
  <link name="link29">
    <visual>
      <origin xyz="0 0 0.05"/>
      <material name="color_f"/>
      <geometry>
        <cylinder length="0.1" radius="0.01"/>
      </geometry>
    </visual>
  </link>
  <link name="link30">
    <visual>
      <origin xyz="0 0 5e-06"/>
      <material name="color_g"/>
      <geometry>
        <cylinder length="1e-05" radius="0.01"/>
      </geometry>
    </visual>
  </link>
  <link name="link31">
    <visual>
      <origin xyz="0 0 0.05"/>
      <material name="color_h"/>
      <geometry>
        <cylinder length="0.1" radius="0.01"/>
      </geometry>
    </visual>
  </link>
  <link name="link32">
    <visual>
      <origin xyz="0 0 5e-06"/>
      <material name="color_a"/>
      <geometry>
        <cylinder length="1e-05" radius="0.01"/>
      </geometry>
    </visual>
  </link>
  <link name="link33">
    <visual>
      <origin xyz="0 0 0.05"/>
      <material name="color_b"/>
      <geometry>
        <cylinder length="0.1" radius="0.01"/>
      </geometry>
    </visual>
  </link>
  <link name="link34">
    <visual>
      <origin xyz="0 0 5e-06"/>
      <material name="color_c"/>
      <geometry>
        <cylinder length="1e-05" radius="0.01"/>
      </geometry>
    </visual>
  </link>
  <link name="link35">
    <visual>
      <origin xyz="0 0 0.05"/>
      <material name="color_d"/>
      <geometry>
        <cylinder length="0.1" radius="0.01"/>
      </geometry>
    </visual>
  </link>
  <link name="link36">
    <visual>
      <origin xyz="0 0 5e-06"/>
      <material name="color_e"/>
      <geometry>
        <cylinder length="1e-05" radius="0.01"/>
      </geometry>
    </visual>
  </link>
  <link name="link37">
    <visual>
      <origin xyz="0 0 0.05"/>
      <material name="color_f"/>
      <geometry>
        <cylinder length="0.1" radius="0.01"/>
      </geometry>
    </visual>
  </link>
  <link name="link38">
    <visual>
      <origin xyz="0 0 5e-06"/>
      <material name="color_g"/>
      <geometry>
        <cylinder length="1e-05" radius="0.01"/>
      </geometry>
    </visual>
  </link>
  <link name="link39">
    <visual>
      <origin xyz="0 0 0.05"/>
      <material name="color_h"/>
      <geometry>
        <cylinder length="0.1" radius="0.01"/>
      </geometry>
    </visual>
  </link>
  <joint name="joint0" type="revolute">
    <parent link="link0"/>
    <child link="link1"/>
    <axis xyz="1 0 0"/>
    <origin xyz="0 0 1e-05"/>
    <limit effort="100" lower="-1.57" upper="1.57" velocity="100"/>
  </joint>
  <joint name="joint1" type="revolute">
    <parent link="link1"/>
    <child link="link2"/>
    <axis xyz="0 1 0"/>
    <origin xyz="0 0 0.1"/>
    <limit effort="100" lower="-1.57" upper="1.57" velocity="100"/>
  </joint>
  <joint name="joint2" type="revolute">
    <parent link="link2"/>
    <child link="link3"/>
    <axis xyz="1 0 0"/>
    <origin xyz="0 0 1e-05"/>
    <limit effort="100" lower="-1.57" upper="1.57" velocity="100"/>
  </joint>
  <joint name="joint3" type="revolute">
    <parent link="link3"/>
    <child link="link4"/>
    <axis xyz="0 1 0"/>
    <origin xyz="0 0 0.1"/>
    <limit effort="100" lower="-1.57" upper="1.57" velocity="100"/>
  </joint>
  <joint name="joint4" type="revolute">
    <parent link="link4"/>
    <child link="link5"/>
    <axis xyz="1 0 0"/>
    <origin xyz="0 0 1e-05"/>
    <limit effort="100" lower="-1.57" upper="1.57" velocity="100"/>
  </joint>
  <joint name="joint5" type="revolute">
    <parent link="link5"/>
    <child link="link6"/>
    <axis xyz="0 1 0"/>
    <origin xyz="0 0 0.1"/>
    <limit effort="100" lower="-1.57" upper="1.57" velocity="100"/>
  </joint>
  <joint name="joint6" type="revolute">
    <parent link="link6"/>
    <child link="link7"/>
    <axis xyz="1 0 0"/>
    <origin xyz="0 0 1e-05"/>
    <limit effort="100" lower="-1.57" upper="1.57" velocity="100"/>
  </joint>
  <joint name="joint7" type="revolute">
    <parent link="link7"/>
    <child link="link8"/>
    <axis xyz="0 1 0"/>
    <origin xyz="0 0 0.1"/>
    <limit effort="100" lower="-1.57" upper="1.57" velocity="100"/>
  </joint>
  <joint name="joint8" type="revolute">
    <parent link="link8"/>
    <child link="link9"/>
    <axis xyz="1 0 0"/>
    <origin xyz="0 0 1e-05"/>
    <limit effort="100" lower="-1.57" upper="1.57" velocity="100"/>
  </joint>
  <joint name="joint9" type="revolute">
    <parent link="link9"/>
    <child link="link10"/>
    <axis xyz="0 1 0"/>
    <origin xyz="0 0 0.1"/>
    <limit effort="100" lower="-1.57" upper="1.57" velocity="100"/>
  </joint>
  <joint name="joint10" type="revolute">
    <parent link="link10"/>
    <child link="link11"/>
    <axis xyz="1 0 0"/>
    <origin xyz="0 0 1e-05"/>
    <limit effort="100" lower="-1.57" upper="1.57" velocity="100"/>
  </joint>
  <joint name="joint11" type="revolute">
    <parent link="link11"/>
    <child link="link12"/>
    <axis xyz="0 1 0"/>
    <origin xyz="0 0 0.1"/>
    <limit effort="100" lower="-1.57" upper="1.57" velocity="100"/>
  </joint>
  <joint name="joint12" type="revolute">
    <parent link="link12"/>
    <child link="link13"/>
    <axis xyz="1 0 0"/>
    <origin xyz="0 0 1e-05"/>
    <limit effort="100" lower="-1.57" upper="1.57" velocity="100"/>
  </joint>
  <joint name="joint13" type="revolute">
    <parent link="link13"/>
    <child link="link14"/>
    <axis xyz="0 1 0"/>
    <origin xyz="0 0 0.1"/>
    <limit effort="100" lower="-1.57" upper="1.57" velocity="100"/>
  </joint>
  <joint name="joint14" type="revolute">
    <parent link="link14"/>
    <child link="link15"/>
    <axis xyz="1 0 0"/>
    <origin xyz="0 0 1e-05"/>
    <limit effort="100" lower="-1.57" upper="1.57" velocity="100"/>
  </joint>
  <joint name="joint15" type="revolute">
    <parent link="link15"/>
    <child link="link16"/>
    <axis xyz="0 1 0"/>
    <origin xyz="0 0 0.1"/>
    <limit effort="100" lower="-1.57" upper="1.57" velocity="100"/>
  </joint>
  <joint name="joint16" type="revolute">
    <parent link="link16"/>
    <child link="link17"/>
    <axis xyz="1 0 0"/>
    <origin xyz="0 0 1e-05"/>
    <limit effort="100" lower="-1.57" upper="1.57" velocity="100"/>
  </joint>
  <joint name="joint17" type="revolute">
    <parent link="link17"/>
    <child link="link18"/>
    <axis xyz="0 1 0"/>
    <origin xyz="0 0 0.1"/>
    <limit effort="100" lower="-1.57" upper="1.57" velocity="100"/>
  </joint>
  <joint name="joint18" type="revolute">
    <parent link="link18"/>
    <child link="link19"/>
    <axis xyz="1 0 0"/>
    <origin xyz="0 0 1e-05"/>
    <limit effort="100" lower="-1.57" upper="1.57" velocity="100"/>
  </joint>
  <joint name="joint19" type="revolute">
    <parent link="link19"/>
    <child link="link20"/>
    <axis xyz="0 1 0"/>
    <origin xyz="0 0 0.1"/>
    <limit effort="100" lower="-1.57" upper="1.57" velocity="100"/>
  </joint>
  <joint name="joint20" type="revolute">
    <parent link="link20"/>
    <child link="link21"/>
    <axis xyz="1 0 0"/>
    <origin xyz="0 0 1e-05"/>
    <limit effort="100" lower="-1.57" upper="1.57" velocity="100"/>
  </joint>
  <joint name="joint21" type="revolute">
    <parent link="link21"/>
    <child link="link22"/>
    <axis xyz="0 1 0"/>
    <origin xyz="0 0 0.1"/>
    <limit effort="100" lower="-1.57" upper="1.57" velocity="100"/>
  </joint>
  <joint name="joint22" type="revolute">
    <parent link="link22"/>
    <child link="link23"/>
    <axis xyz="1 0 0"/>
    <origin xyz="0 0 1e-05"/>
    <limit effort="100" lower="-1.57" upper="1.57" velocity="100"/>
  </joint>
  <joint name="joint23" type="revolute">
    <parent link="link23"/>
    <child link="link24"/>
    <axis xyz="0 1 0"/>
    <origin xyz="0 0 0.1"/>
    <limit effort="100" lower="-1.57" upper="1.57" velocity="100"/>
  </joint>
  <joint name="joint24" type="revolute">
    <parent link="link24"/>
    <child link="link25"/>
    <axis xyz="1 0 0"/>
    <origin xyz="0 0 1e-05"/>
    <limit effort="100" lower="-1.57" upper="1.57" velocity="100"/>
  </joint>
  <joint name="joint25" type="revolute">
    <parent link="link25"/>
    <child link="link26"/>
    <axis xyz="0 1 0"/>
    <origin xyz="0 0 0.1"/>
    <limit effort="100" lower="-1.57" upper="1.57" velocity="100"/>
  </joint>
  <joint name="joint26" type="revolute">
    <parent link="link26"/>
    <child link="link27"/>
    <axis xyz="1 0 0"/>
    <origin xyz="0 0 1e-05"/>
    <limit effort="100" lower="-1.57" upper="1.57" velocity="100"/>
  </joint>
  <joint name="joint27" type="revolute">
    <parent link="link27"/>
    <child link="link28"/>
    <axis xyz="0 1 0"/>
    <origin xyz="0 0 0.1"/>
    <limit effort="100" lower="-1.57" upper="1.57" velocity="100"/>
  </joint>
  <joint name="joint28" type="revolute">
    <parent link="link28"/>
    <child link="link29"/>
    <axis xyz="1 0 0"/>
    <origin xyz="0 0 1e-05"/>
    <limit effort="100" lower="-1.57" upper="1.57" velocity="100"/>
  </joint>
  <joint name="joint29" type="revolute">
    <parent link="link29"/>
    <child link="link30"/>
    <axis xyz="0 1 0"/>
    <origin xyz="0 0 0.1"/>
    <limit effort="100" lower="-1.57" upper="1.57" velocity="100"/>
  </joint>
  <joint name="joint30" type="revolute">
    <parent link="link30"/>
    <child link="link31"/>
    <axis xyz="1 0 0"/>
    <origin xyz="0 0 1e-05"/>
    <limit effort="100" lower="-1.57" upper="1.57" velocity="100"/>
  </joint>
  <joint name="joint31" type="revolute">
    <parent link="link31"/>
    <child link="link32"/>
    <axis xyz="0 1 0"/>
    <origin xyz="0 0 0.1"/>
    <limit effort="100" lower="-1.57" upper="1.57" velocity="100"/>
  </joint>
  <joint name="joint32" type="revolute">
    <parent link="link32"/>
    <child link="link33"/>
    <axis xyz="1 0 0"/>
    <origin xyz="0 0 1e-05"/>
    <limit effort="100" lower="-1.57" upper="1.57" velocity="100"/>
  </joint>
  <joint name="joint33" type="revolute">
    <parent link="link33"/>
    <child link="link34"/>
    <axis xyz="0 1 0"/>
    <origin xyz="0 0 0.1"/>
    <limit effort="100" lower="-1.57" upper="1.57" velocity="100"/>
  </joint>
  <joint name="joint34" type="revolute">
    <parent link="link34"/>
    <child link="link35"/>
    <axis xyz="1 0 0"/>
    <origin xyz="0 0 1e-05"/>
    <limit effort="100" lower="-1.57" upper="1.57" velocity="100"/>
  </joint>
  <joint name="joint35" type="revolute">
    <parent link="link35"/>
    <child link="link36"/>
    <axis xyz="0 1 0"/>
    <origin xyz="0 0 0.1"/>
    <limit effort="100" lower="-1.57" upper="1.57" velocity="100"/>
  </joint>
  <joint name="joint36" type="revolute">
    <parent link="link36"/>
    <child link="link37"/>
    <axis xyz="1 0 0"/>
    <origin xyz="0 0 1e-05"/>
    <limit effort="100" lower="-1.57" upper="1.57" velocity="100"/>
  </joint>
  <joint name="joint37" type="revolute">
    <parent link="link37"/>
    <child link="link38"/>
    <axis xyz="0 1 0"/>
    <origin xyz="0 0 0.1"/>
    <limit effort="100" lower="-1.57" upper="1.57" velocity="100"/>
  </joint>
  <joint name="joint38" type="revolute">
    <parent link="link38"/>
    <child link="link39"/>
    <axis xyz="1 0 0"/>
    <origin xyz="0 0 1e-05"/>
    <limit effort="100" lower="-1.57" upper="1.57" velocity="100"/>
  </joint>
  <material name="end_effector_material">
    <color rgba="1 1 1 1"/>
  </material>
  <link name="end_effector">
    <visual>
      <origin xyz="0 0 0.1"/>
      <material name="end_effector_material"/>
      <geometry>
        <sphere radius="0.1"/>
      </geometry>
    </visual>
  </link>
  <joint name="joint_end_effector" type="fixed">
    <parent link="link39"/>
    <child link="end_effector"/>
    <limit effort="100" lower="-1.57" upper="1.57" velocity="100"/>
  </joint>
</robot>

